Workbook

Sheet #Sommaire
A2: ID unique | B2: Objet(s) niveau 1 (MDD) | C2: Libellé de la donnée (MDD) | D2: Description | E2: Référentiel source | F2: Nom de la nomenclature | G2: Lien | H2: Statut Nomenclature | I2: RC-EDA | J2: RS-EDA | K2: RS-EDA-MAJ | L2: RS-RPIS | M2: RS-BPV | N2: RS-RI | O2: RS-DR | P2: RS-RR | Q2: RS-SR | R2: RC-REF
A3: HubSante.filiere | B3: Filiere | C3: Filiere | D3: =Filiere!$B$5 -> Décrit la filière compétente pour traiter le dossier. | E3: =Filiere!$B$2 -> ENUM | F3: =Filiere!$B$3 -> FILIERE | G3: Lien nomenclature | H3: V1 validée métier | J3: X | K3: X
A4: HubSante.intervention | B4: Type d'intervention | C4: Type d'intervention | D4: ='Type d''intervention'!$B$5 -> Décrit le type d'intervention (primaire, secondaire, etc.) | E4: ='Type d''intervention'!$B$2 -> ENUM | F4: ='Type d''intervention'!$B$3 -> TYPE_Intervention | G4: Lien nomenclature | H4: V1 validée métier | J4: X
A5: HubSante.origine | B5: Qualification de l'affaire/dossier | C5: Origine de l'appel | D5: ='Origine de l''appel'!$B$5 -> Décrit l'origine de l'appel | E5: ='Origine de l''appel'!$B$2 -> ENUM | F5: ='Origine de l''appel'!$B$3 -> ORIGINE | G5: Lien nomenclature | H5: V1 validée métier | J5: X
A6: HubSante.fait | B6: Qualification de l'affaire/dossier | C6: Nature de fait | D6: ='Nature de fait'!$B$5 -> Décrit la nature de fait de l'affaire/dossier | E6: ='Nature de fait'!$B$2 -> CISU | F6: ='Nature de fait'!$B$3 -> Code_Nature_de_fait | G6: Lien nomenclature | H6: V2.3 validée CISU | I6: X | J6: X | L6: X
A7: HubSante.lieu | B7: Qualification de l'affaire/dossier | C7: Type de lieu | D7: ='Type de lieu'!$B$5 -> Décrit le type de lieu où se situe l'affaire/dossier | E7: ='Type de lieu'!$B$2 -> CISU | F7: ='Type de lieu'!$B$3 -> Code_Type_de_lieu | G7: Lien nomenclature | H7: V2.3 validée CISU | I7: X | J7: X | L7: X | M7: X
A8: HubSante.risque | B8: Qualification de l'affaire/dossier | C8: Risque, menace et sensibilité | D8: ='Risque, menace et sensibilité'!$B$5 -> Décrit les risques, menaces ou sensibilités de l'affaire/dossier | E8: ='Risque, menace et sensibilité'!$B$2 -> CISU | F8: ='Risque, menace et sensibilité'!$B$3 -> Code_Risque-Menace-Sensibilité | G8: Lien nomenclature | H8: V2.3 validée CISU | I8: X | J8: X | K8: X
A9: HubSante.motif | B9: Qualification de l'affaire/dossier | C9: Motif de recours médico-secouriste | D9: ='Motif de recours médico-secouri'!$B$5 -> Décrit le motif de recours médico-secouriste. | E9: ='Motif de recours médico-secouri'!$B$2 -> CISU | F9: ='Motif de recours médico-secouri'!$B$3 -> Code_Motif_patient-victime | G9: Lien nomenclature | H9: V2.3 validée CISU | I9: X | J9: X | L9: X
A10: HubSante.etat | B10: Qualification de l'affaire/dossier | C10: Etat du dossier | D10: ='Etats du dossier'!$B$5 -> Décrit la filière compétente pour traiter le dossier. | E10: ='Etats du dossier'!$B$2 -> ENUM | F10: ='Etats du dossier'!$B$3 -> Etats_Dossier | G10: Lien nomenclature | H10: V1 validée métier | J10: X | K10: X
A11: HubSante.nbVictimes | B11: Qualification de l'affaire/dossier | C11: Nombre de patients-victimes | D11: ='Nombre de patients-victimes'!$B$5 -> Décrit le nombre de patient/victimes | E11: ='Nombre de patients-victimes'!$B$2 -> ENUM | F11: ='Nombre de patients-victimes'!$B$3 -> NOMBRE_Patient_Victime | G11: Lien nomenclature | H11: V1 validée métier | I11: X
A12: HubSante.patient | B12: Qualification de l'affaire/dossier | C12: Type du patient-victime | D12: ='Type du patient-victime'!$B$5 -> Décrit le type de patient/victime principal | E12: ='Type du patient-victime'!$B$2 -> ENUM | F12: ='Type du patient-victime'!$B$3 -> TYPE_Patient_Victime | G12: Lien nomenclature | H12: V1 validée métier | I12: X
A13: HubSante.attribution | B13: Qualification de l'affaire/dossier | C13: Attribution du dossier | D13: ='Attribution du dossier'!$B$5 -> Décrit le type de dossier, et son attribution | E13: ='Attribution du dossier'!$B$2 -> SI-SAMU | F13: ='Attribution du dossier'!$B$3 -> DEVENIRD | G13: Lien nomenclature | H13: V1 validée métier | J13: X
A14: HubSante.priorite | B14: Qualification de l'affaire/dossier | C14: Priorité de régulation médicale | D14: ='Priorité de régulation médicale'!$B$5 -> Décrit la priorité de régulation médicale. | E14: ='Priorité de régulation médicale'!$B$2 -> SI-SAMU | F14: ='Priorité de régulation médicale'!$B$3 -> PRIORITE | G14: Lien nomenclature | H14: V1 validée métier | J14: X | K14: X
A15: HubSante.idLieu | B15: Localisation | C15: Lieu - Source ou type d'id | D15: ='Lieu - Source ou type d''id'!$B$5 -> Décrit le type d'idenfiant possible pour un lieu (société / établissement) | E15: ='Lieu - Source ou type d''id'!$B$2 -> ENUM | F15: ='Lieu - Source ou type d''id'!$B$3 -> SOURCE_Id_Lieu | G15: Lien nomenclature | H15: V1 validée métier | I15: X | J15: X | K15: X
A16: HubSante.precision | B16: Localisation | C16: Precision | D16: =Precision!$B$5 -> Décrit le niveau de précision des coordonnées GPS envoyées | E16: =Precision!$B$2 -> ENUM | F16: =Precision!$B$3 -> PRECISION | G16: Lien nomenclature | H16: V1 validée métier | I16: X | J16: X
A17: HubSante.systeme | B17: Localisation | C17: Nom de la source | D17: ='Nom de la source'!$B$5 -> Décrit le système fournissant le localisant | E17: ='Nom de la source'!$B$2 -> ENUM | F17: ='Nom de la source'!$B$3 -> SOURCE_Loc | G17: Lien nomenclature | H17: V1 validée métier | I17: X | J17: X | K17: X
A18: HubSante.objetSource | B18: Localisation | C18: Type d'objet | D18: ='Type d''objet'!$B$5 -> Décrit le type d'objet dans le système | E18: ='Type d''objet'!$B$2 -> ENUM | F18: ='Type d''objet'!$B$3 -> TYPE_Objet_Sys | G18: Lien nomenclature | H18: V1 validée métier | I18: X | J18: X | K18: X
A19: HubSante.signalement | B19: Alerte initiale | C19: Signalement | D19: =Signalement!$B$5 -> Décrit le niveau de signalement de l'alerte | E19: =Signalement!$B$2 -> ENUM | F19: =Signalement!$B$3 -> SIGNALEMENT | G19: Lien nomenclature | H19: V1 validée métier | I19: X
A20: HubSante.canal | B20: Alerte initiale | C20: Canal | D20: =Canal!$B$5 -> Décrit le type de canal utilisé pour le contact | E20: =Canal!$B$2 -> ENUM | F20: =Canal!$B$3 -> CONTACT_Canal | G20: Lien nomenclature | H20: V1 validée métier | I20: X | J20: X
A21: HubSante.typeCom | B21: Alerte initiale | C21: Type de contact | D21: ='Type de contact'!$B$5 -> Décrit le type de contact | E21: ='Type de contact'!$B$2 -> ENUM | F21: ='Type de contact'!$B$3 -> CONTACT_Type | G21: Lien nomenclature | H21: V1 validée métier | I21: X | J21: X | K21: X
A22: HubSante.langue | C22: Langue | D22: =Langue!B5 -> Décrit la langue parlée par l'appelant / le requérant. Source : https://www.loc.gov/standards/iso639-2/php/code_list.php | E22: =Langue!B2 -> ISO-639.1 | F22: =Langue!B3 -> LANGUE | G22: Lien nomenclature | H22: Validée | I22: X | J22: X
A23: HubSante.typeAppelant | B23: Alerte initiale | C23: Type de requérant | D23: ='Type de requérant'!$B$5 -> Décrit le type de requérant/appelant | E23: ='Type de requérant'!$B$2 -> SI-SAMU | F23: ='Type de requérant'!$B$3 -> TYPAPPLT | G23: Lien nomenclature | H23: V1 validée métier | I23: X | J23: X
A24: HubSante.communication | B24: Alerte initiale | C24: Difficultés de communication | D24: ='Difficultés de communication'!$B$5 -> Décrit les difficultés de communication potentielles du requérant/appelant | E24: ='Difficultés de communication'!$B$2 -> SI-SAMU | F24: ='Difficultés de communication'!$B$3 -> PBAPL | G24: Lien nomenclature | H24: V1 validée métier | I24: X | J24: X
A25: HubSante.typeIdPatient | B25: Patient | C25: Patient - type d'Id | D25: ='Patient - type d''Id'!$B$5 -> Décrit le type d'identifiant fourni | E25: ='Patient - type d''Id'!$B$2 -> ENUM | F25: ='Patient - type d''Id'!$B$3 -> TYPE_Id_Patient | G25: Lien nomenclature | H25: V1 validée métier | J25: X | K25: X | M25: X
A26: HubSante.sexe | B26: Patient | C26: Sexe | D26: =Sexe!$B$5 -> Décrit le sexe du patient | E26: =Sexe!$B$2 -> NOS | F26: =Sexe!$B$3 -> NOMENC_SEXE | G26: Lien nomenclature | H26: Validée | I26: X | J26: X | K26: X | L26: X | M26: X
A27: HubSante.niveauSoin | B27: Qualification / Patient | C27: Niveau de soin | D27: ='Niveau de soin'!$B$5 -> Décrit le niveau de soins : le plus grave est retenu pour qualifier le dossier/affaire. Pour chaque patient/victime, le motif spécifique est indiqué. | E27: ='Niveau de soin'!$B$2 -> SI-SAMU | F27: ='Niveau de soin'!$B$3 -> GRAVITE | G27: Lien nomenclature | H27: V1 validée métier | J27: X | K27: X
A28: HubSante.role | B28: Observation médicale | C28: Role | D28: =Role!$B$5 -> Décrit le rôle de l'opérateur dans l'organisation à laquelle il appartient | E28: =Role!$B$2 -> ENUM | F28: =Role!$B$3 -> ROLE | G28: Lien nomenclature | H28: V1 validée métier | J28: X | K28: X | M28: X
A29: HubSante.typeDecision | B29: Décisions | C29: Type de decision | D29: ='Type de decision'!$B$5 -> Décrit le type de décision prise | E29: ='Type de decision'!$B$2 -> SI-SAMU | F29: ='Type de decision'!$B$3 -> TYPEDEC | G29: Lien nomenclature | H29: V1 validée métier | J29: X | K29: X
A30: HubSante.typeRessource | B30: Décisions / Ressource engagée | C30: Type de ressource | D30: ='Type de ressource'!$B$5 -> Décrit le type de moyen/ressources, dans un sens plus large que type de vecteur/véhicule. N.B. dans OPG pour les message EMSI. | E30: ='Type de ressource'!$B$2 -> SI-SAMU | F30: ='Type de ressource'!$B$3 -> TYPE_MOYEN | G30: Lien nomenclature | H30: V1 validée métier | J30: X | K30: X | L30: X | P30: X
A31: HubSante.typeVecteur | B31: Décisions / Ressource engagée | C31: Type de vecteurs | D31: ='Type de vecteurs'!$B$5 -> Décrit le type de vecteur/véhicule ou de ressource mobilisée, avec plus de précision que simplement le type de ressources. Utilisée exclusivement en inter-santé (cf. EMSI-OPG pour 15-NexSIS) | E31: ='Type de vecteurs'!$B$2 -> SI-SAMU | F31: ='Type de vecteurs'!$B$3 -> TYPE_VECTEUR | G31: Lien nomenclature | H31: V1 validée métier | L31: X | N31: X | P31: X
A32: HubSante.typePEC | B32: Ressource engagée | C32: Niveau de prise en charge | D32: ='Niveau de prise en charge'!$B$5 -> Décrit le niveau de prise en charge exigé. | E32: ='Niveau de prise en charge'!$B$2 -> SI-SAMU | F32: ='Niveau de prise en charge'!$B$3 -> NIVSOIN | G32: Lien nomenclature | H32: V1 validée métier | L32: X | N32: X
A33: HubSante.typeOrientation | B33: Décisions | C33: Type d'orientation | D33: ='Type de destination'!$B$5 -> Décrit la filière compétente pour traiter le dossier. | E33: ='Type de destination'!$B$2 -> ENUM | F33: ='Type de destination'!$B$3 -> TYPE_Destination | G33: Lien nomenclature | H33: V1 validée métier | J33: X | K33: X
A34: HubSante.effet | B34: Demande de ressource | C34: Effet à obtenir | D34: ='Effet à obtenir'!$B$5 -> Décrit les effets à obtenir utilisés uniquement entre SAMU, en intersanté. | E34: ='Effet à obtenir'!$B$2 -> CISU | F34: ='Effet à obtenir'!$B$3 -> Code_Effet_a_obtenir | G34: Lien nomenclature | H34: V2.3 validée CISU | O34: X
A35: HubSante.cadre | B35: Demande de ressource | C35: Cadre conventionnel | D35: ='Cadre conventionnel'!$B$5 -> Décrit le cadre conventionnel dans lequel s'inscrit une demande de ressources. Codes inter-santé uniquement (voir EMSI pour lien 15-Nexsis). | E35: ='Cadre conventionnel'!$B$2 -> CISU | F35: ='Cadre conventionnel'!$B$3 -> CADRE_CONV | G35: Lien nomenclature | H35: V2.3 validée CISU | O35: X
A36: HubSante.delai | B36: Demande de ressource | C36: Delai d'intervention | D36: ='Delai d''intervention'!$B$5 -> Décrit le délai d'intervention attendu ou souhaité pour une ressource ou un vecteur. | E36: ='Delai d''intervention'!$B$2 -> SI-SAMU | F36: ='Delai d''intervention'!$B$3 -> DELAI | G36: Lien nomenclature | H36: V1 validée métier | O36: X | P36: X
A37: HubSante.etatDemande | B37: resourcesRequest | C37: Etat annulation | D37: ='Annulation DR'!$B$5 -> Décrit l'état de l'annulation de demande de ressources | E37: ='Annulation DR'!B2 -> ENUM | F37: ='Annulation DR'!B3 -> STATUS_DR | G37: Lien nomenclature | H37: V1 validée métier | O37: X
A38: HubSante.reponseDemande | B38: Réponse à la demande de ressources | C38: Reponse demande ressources | D38: ='Reponse demande ressources'!$B$5 -> Décrit la réponse à une demande de ressources | E38: ='Reponse demande ressources'!$B$2 -> ENUM | F38: ='Reponse demande ressources'!$B$3 -> REPONSE | G38: Lien nomenclature | H38: V1 validée métier | P38: X
A39: HubSante.statutVecteur | B39: Ressource engagée / resourcesStatus | C39: Statut du vecteur | D39: ='Statut du vecteur'!$B$5 -> Décrit le statut du vecteur/véhicule mobilisé | E39: ='Statut du vecteur'!$B$2 -> SI-SAMU | F39: ='Statut du vecteur'!$B$3 -> STATUS_VECTEUR | G39: Lien nomenclature | H39: V1 validée métier | N39: X | Q39: X
A40: HubSante.etape | C40: Etape d'intégration du dossier | D40: ='Etape message'!B5 -> Décrit les différentes étapes d'intégration et de consultation du dossier dans un système | E40: ='Etape message'!B2 -> ENUM | F40: ='Etape message'!B3 -> Etape_Message | G40: Lien nomenclature | H40: V1 hub Santé | R40: X

Sheet Filiere
A1: Identifiant nomenclature | B1: HubSante.filiere
A2: Référentiel nomenclature | B2: ENUM
A3: Nom Nomenclature | B3: FILIERE
A4: Nombre de niveau | B4: 1
A5: Description | B5: Décrit la filière compétente pour traiter le dossier.
A6: Code | B6: Libellé niveau 1 | C6: Libellé niveau 2 | D6: Description | E6: Commentaire
A7: AMU | B7: Aide Médicale d'Urgence | D7: Filière dédiée à l'aide médicale d'urgence
A8: NEONAT | B8: Néonatalité | D8: Filière dédiée à la néonatalité
A9: PSY | B9: Psychiatrie | D9: Filière dédiée à la psychiatrie
A10: SNP | B10: Soins Non Programmés | D10: Filière dédiée aux soins non programmés

Sheet Type d'intervention
A1: Identifiant nomenclature | B1: HubSante.intervention
A2: Référentiel nomenclature | B2: ENUM
A3: Nom Nomenclature | B3: TYPE_Intervention
A4: Nombre de niveau | B4: 1
A5: Description | B5: Décrit le type d'intervention (primaire, secondaire, etc.)
A6: Code | B6: Libellé niveau 1 | C6: Libellé niveau 2 | D6: Description | E6: Commentaire
A7: T1 | B7: Primaire | D7: Prise en charge médicale spécialisée d’un ou de plusieurs patients ne se trouvant pas admis dans un établissement de santé et dont l’état requiert de façon urgente une expertise médicale pour des soins d’urgences ou de réanimation et pour leur orientation.
A8: T2-INTER | B8: Transfert Inter Hospitalier | D8: Prise en charge médicale spécialisée d’un patient hospitalisé ou pris en charge par un service (d’urgences ou non), au sein d’un établissement de santé vers un établissement de santé ne faisant pas partie de la même entité juridique, que le transport ait finalement lieu ou non.
A9: T2-INTRA | B9: Transfert Intra Hospitalier | D9: Prise en charge médicale spécialisée d’un patient hospitalisé ou pris en charge par un service (d’urgences ou non), au sein d’un établissement de santé vers n même établissement de santé ou entre deux établissements de santé appartenant à la même entité juridique.
A10: T3 | B10: Retour | D10: Prise en charge médicale spécialisée d’un patient hospitalisé en vue de son retour à son domicile ou dans une structure n’étant pas un établissement de santé (par exemple un EHPAD).
A11: T4 | B11: Rapat/Evasan | D11: Prise en charge médicale spécialisée d’un patient en vue de son transport le plus souvent vers un établissement de soins, par exemple dans le cadre d’un rapprochement familial.

Sheet Origine de l'appel
A1: Identifiant nomenclature | B1: HubSante.origine
A2: Référentiel nomenclature | B2: ENUM
A3: Nom Nomenclature | B3: ORIGINE
A4: Nombre de niveau | B4: 1
A5: Description | B5: Décrit l'origine de l'appel
A6: Code | B6: Libellé niveau 1 | C6: Libellé niveau 2 | D6: Description | E6: Commentaire
A7: 15 | B7: Ligne 15 | D7: Le requérant a contacté directement le CRRA en composant le 15.
A8: 116117 | B8: Ligne PDSA | D8: Le requérant a contacté directement le CRRA en composant le numéro d’une ligne PDSA (116117 et autres lignes encore fonctionnelles)
A9: AUTOCOM | B9: Ligne hôpital | D9: Le requérant a contacté directement le CRRA en composant un numéro interne de l’établissement de santé siège du Samu Centre 15.
A10: 112 | B10: Ligne 112 | D10: Le requérant a contacté directement le CRRA en composant le numéro 112
A11: 115 | B11: Ligne 115 | D11: Le requérant a contacté directement le CRRA en composant le numéro 115
A12: CRRA | B12: CRRA (autres lignes) | D12: Le requérant a contacté directement le CRRA en composant un autre numéro pour contacter le Samu – Centre 15.
A13: AUTREC15 | B13: Autre CRRA | D13: Le requérant a contacté en premier un autre Samu Centre 15 qui a retransmis l’appel au CRRA
A14: CTA-CONF | B14: CTA-CODIS en conf | D14: Le requérant a contacté en premier le ou les CTA CODIS correspondant(s) habituel(s) du Samu qui a retransmis l’appel au CRRA ; appel avec mise en interconnexion par conférence.
A15: CTA-PI | B15: CTA-CODIS pour info | D15: Le requérant a contacté en premier le ou les CTA CODIS correspondant(s) habituel(s) du Samu qui a retransmis l’appel au CRRA ; appel avec simple information.
A16: AUTRECTA | B16: Autre CTA-CODIS | D16: Le requérant a contacté en premier un CTA CODIS distant qui n’est pas un correspondant habituel du Samu qui a retransmis l’appel au CRRA.
A17: CNR | B17: CNR 114 | D17: Le requérant a contacté en premier le centre national relais pour les sourds et malentendants qui a retransmis l’appel au CRRA.
A18: FDO | B18: CORG, CIC | D18: Le requérant a contacté en premier un standard de forces de l’ordre (police, gendarmerie, …) qui a retransmis l’appel au CRRA.
A19: SNATED | B19: Ligne 119 (SNATED) | D19: Le requérant a contacté en premier le standard de la protection de l’enfance qui a retransmis l’appel au CRRA.
A20: PDSSOS | B20: Asso PDSA et SOS | D20: Le requérant a contacté en premier un standard d’une association de PDSA, type SOS médecins ou autres qui a retransmis l’appel au CRRA.
A21: TELASSIST | B21: Téléassistance | D21: Le requérant a contacté en premier une structure de télésurveillance ou d’assistance médicale qui a retransmis l’appel au CRRA.
A22: CROSS | B22: CROSS | D22: Le requérant a contacté en premier une structure publique d’urgence type CROSS maritime qui a retransmis l’appel au CRRA.
A23: PUBLIC | B23: Autre centre d'appel | D23: Le requérant a contacté en premier une structure publique d’urgence type associations ne participant pas à la PDSA, … qui a retransmis l’appel au CRRA.
... A25: AUTRE | B25: Autre structure | D25: Si le central d’appel d’urgence est déterminé mais ne fait pas partie des choix précédents ou lorsque l’information n’est pas disponible.

Sheet Nature de fait
A1: Identifiant nomenclature | B1: HubSante.fait
A2: Référentiel nomenclature | B2: CISU
A3: Nom Nomenclature | B3: Code_Nature_de_fait
A4: Nombre de niveau | B4: 3
A5: Description | B5: Décrit la nature de fait de l'affaire/dossier
A6: Code | B6: Libellé niveau 1 | C6: Libellé niveau 2 | D6: Libellé niveau 3 | E6: Description | F6: Commentaire
A7: C01.00.00 | B7: Accident de la circulation
A8: C01.01.00 | C8: Accident routier non suivi de feu
A9: C01.01.01 | D9: Accident routier véhicule léger / fourgon, non suivi de feu | E9: Catégorie de véhicules qui regroupe les voitures de tourisme et les véhicules utilitaires (jusqu'à 3,5 tonnes)
A10: C01.01.02 | D10: Accident routier camion de marchandises, non suivi de feu | E10: Poids lourd de plus de 3,5 tonnes affecté au transport de biens et embarquant donc un nombre réduit de passagers
A11: C01.01.03 | D11: Accident routier bus / car / autocar, non suivi de feu | E11: Véhicule de grande dimension affecté au transport de passagers
A12: C01.01.04 | D12: Accident routier 2-roues, non suivi de feu | E12: Tout véhicule à deux roues, avec ou sans moteur (bicyclette, cyclomoteur, motocyclette, …), l’implication d'un 2 roues « l'emporte » sur les autres types de moyens routiers
A13: C01.01.05 | D13: Accident routier piéton, non suivi de feu | E13: L’implication d'un piéton « l'emporte » sur les autres types de moyens routiers
A14: C01.01.06 | D14: Accident routier : carambolage non suivi de feu | E14: Série de chocs, de collisions impliquant 4 véhicules et plus, la notion de carambolage « l'emporte » sur les autres types d'accidents routiers
A15: C01.01.07 | D15: Accident routier d'engin de chantier/agricole, non suivi de feu
A16: C01.06.00 | C16: Accident routier suivi de feu
A17: C01.06.01 | D17: Accident routier véhicule léger / fourgon, suivi de feu
A18: C01.06.02 | D18: Accident routier poids lourd, suivi de feu
A19: C01.06.03 | D19: Accident routier bus / car / autocar, suivi de feu
A20: C01.06.04 | D20: Accident routier avec plusieurs véhicules légers, suivi de feu
A21: C01.06.05 | D21: Accident routier : carambolage suivi de feu
A22: C01.02.00 | C22: Accident ferroviaire | E22: L’implication d'un train « l'emporte » sur les moyens routiers
A23: C01.02.01 | D23: Accident train de voyageurs | E23: Tout moyen de transport de personnes par voie ferroviaire
A24: C01.02.02 | D24: Accident train de marchandises | E24: Tout moyen de transport de marchandises par voie ferroviaire
A25: C01.02.03 | D25: Collision train - piéton
A26: C01.02.04 | D26: Collision tramway - piéton
A27: C01.02.05 | D27: Déraillement train de voyageurs
A28: C01.02.06 | D28: Déraillement train de marchandises
A29: C01.02.07 | D29: Déraillement tram, tramway
A30: C01.03.00 | C30: Accident maritime ou fluvial
A31: C01.03.05 | D31: Accident bateau de plaisance / sports nautiques
A32: C01.03.01 | D32: Accident ferry / paquebot | E32: Tout moyen de transport de personnes par voie maritime, avec ou sans moteur (voilier, navire de plaisance, paquebot de croisière, …)
A33: C01.03.02 | D33: Accident bateau de marchandises | E33: Tout moyen de transport de marchandises par voie maritime, avec ou sans moteur (barque, navire de pêche, cargo, …)
A34: C01.03.03 | D34: Accident bateau de pêche
A35: C01.03.04 | D35: Accident bateau de guerre
A36: C01.04.00 | C36: Accident aérien
A37: C01.04.01 | D37: Accident aéronef de marchandises | E37: Tout moyen de transport de marchandises par voie aérienne embarquant au moins 1 pilote à son bord
A38: C01.04.02 | D38: Accident aéronef de ligne | E38: Tout moyen de transport de personnes par voie aérienne embarquant au moins 1 pilote à son bord
A39: C01.04.03 | D39: Accident aéronef militaire | E39: Tout moyen de transport militaire par voie aérienne embarquant au moins 1 pilote à son bord
A40: C01.04.04 | D40: Accident de drone | E40: Petit avion sans équipage embarqué, télécommandé ou programmé
...

Sheet Type de lieu
A1: Identifiant nomenclature | B1: HubSante.lieu
A2: Référentiel nomenclature | B2: CISU
A3: Nom Nomenclature | B3: Code_Type_de_lieu
A4: Nombre de niveau | B4: 3
A5: Description | B5: Décrit le type de lieu où se situe l'affaire/dossier
A6: Code | B6: Libellé niveau 1 | C6: Libellé niveau 2 | D6: Libellé niveau 3 | E6: Description | F6: Commentaire
A7: L01.00.00 | B7: Domicile
A8: L01.01.00 | C8: Maison particulière, pavillon
A9: L01.01.01 | D9: A l'intérieur d'une maison | E9: Enceinte fermée et couverte dont l’accès est potentiellement verrouillé, à renseigner en l’absence d’information plus précise sur la pièce où se situe la personne concernée
A10: L01.01.02 | D10: A l'extérieur d'une maison | E10: Abords, terrasse, jardin, … non couvert
A11: L01.01.03 | D11: Piscine / bassin d'une maison | E11: Privée, enterrée ou non, fixe ou non
A12: L01.01.04 | D12: Dépendance d'une maison | E12: Abri indépendant du domicile de type garage, atelier, abri de jardin, grange, etc.
A13: L01.01.05 | D13: Toiture/Combles d'une maison
A14: L01.02.00 | C14: Lieu d'habitation collectif ou foyer d'hébergement
A15: L01.02.01 | D15: A l'intérieur de l'immeuble (sans précision) | E15: Enceinte fermée et couverte dont l’accès est potentiellement verrouillé, à renseigner en l’absence d’information plus précise sur la pièce où se situe la personne concernée
A16: L01.02.02 | D16: A l'extérieur de l'immeuble | E16: Abords, terrasse, jardin, … non couvert
A17: L01.02.03 | D17: A l'intérieur d'un appartement
A18: L01.02.04 | D18: Entrée / couloir / espaces communs de l'immeuble | E18: Hors escalier
A19: L01.02.05 | D19: Ascenseur
A20: L01.02.06 | D20: Cave / sous-sol / garage /parking d'un immeuble d'habitation
A21: L01.02.07 | D21: Toiture de l'immeuble
A22: L01.02.08 | D22: Comble de l'immeuble
A23: L01.02.09 | D23: Piscine de l'immeuble | E23: Privée, enterrée ou non, fixe ou non
A24: L01.02.10 | D24: Escaliers de l'immeuble
A25: L01.02.11 | D25: Local technique de l'immeuble | E25: Chaufferie, gaine d'ascenseur
A26: L01.02.12 | D26: Dépendance de l'immeuble | E26: Abri indépendant du domicile de type garage, atelier, abri de jardin, grange, etc.
A27: L01.02.13 | D27: Local poubelle / vide ordure de l'immeuble
A28: L01.02.14 | D28: Balcon/terrasse de l'immeuble
A29: L01.03.00 | C29: Habitat spécifique
A30: L01.03.01 | D30: Péniche
A31: L01.03.02 | D31: Mobil-home
A32: L01.03.03 | D32: Habitat précaire
A33: L01.03.04 | D33: Campement
A34: L01.03.05 | D34: Grande demeure / château / manoir
A35: L01.03.06 | D35: Chaumière
A36: L01.04.00 | C36: Autre type de domicile
A37: L02.00.00 | B37: Circulation/transport
A38: L02.01.00 | C38: Voie publique hors voie rapide | E38: Voie sans aucune séparation de chaussée
A39: L02.01.01 | D39: Tunnel (hors voie rapide)
A40: L02.01.02 | D40: Piste cyclable
...

Sheet Risque, menace et sensibilité
A1: Identifiant nomenclature | B1: HubSante.risque
A2: Référentiel nomenclature | B2: CISU
A3: Nom Nomenclature | B3: Code_Risque-Menace-Sensibilité
A4: Nombre de niveau | B4: 1
A5: Description | B5: Décrit les risques, menaces ou sensibilités de l'affaire/dossier
A6: Code | B6: Libellé niveau 1 | C6: Description | D6: Commentaire
A7: R01 | B7: Dommage exclusivement matériel | C7: Usage métier DGGN permettant la graduation matériel / corporel / mortel
A8: R02 | B8: Auteur(s) en fuite
A9: R03 | B9: Présence d’individu(s) ou public menaçant
A10: R04 | B10: Présence d’individu(s) muni(s) d’une arme blanche
A11: R05 | B11: Présence d’individu(s) muni(s) d’une arme à feu
A12: R06 | B12: Suspicion d'attaque terroriste
A13: R07 | B13: Présence de matière ou matériel dangereux | C13: Ex : armes, matière dangereuse non identifiée
A14: R08 | B14: Présence de matière radiologique ou nucléaire civile ou militaire | C14: A saisir si le caractère civil ou militaire n’est pas connu
A15: R11 | B15: Présence de matière bactériologique
A16: R12 | B16: Présence de matière chimique
A17: R13 | B17: Risque d'explosion, présence de gaz
A18: R14 | B18: Risque lié à l'incendie
A19: R15 | B19: Risque d'effondrement
A20: R16 | B20: Présence d'animal dangereux
A21: R17 | B21: Nuée d'insectes
A22: R18 | B22: Inondation
A23: R19 | B23: Risque électrique/ risque lié à une ligne HT ou THT | C23: HT / THT : Haute Tension / Très Haute Tension
A24: R20 | B24: Difficulté d’accès sur site | C24: Ex : milieu montagneux hors voie carrossable
A25: R21 | B25: Difficulté d’accès au patient/victime | C25: Ex : porte verrouillée
A26: R22 | B26: Gêne à la circulation
A27: R23 | B27: Implication d’un élus | C27: En vue d’un traitement avec remontée hiérarchique
A28: R24 | B28: Implication d’un agent public | C28: En vue d’un traitement sans remontée hiérarchique systématique
A29: R25 | B29: Implication d’une personnalité | C29: Ex : VIP
A30: R26 | B30: Implication de plusieurs personnes (2 à 10) | C30: En vue de permettre aux forces de sécurité d’adapter leur dispositif d’intervention. Les autres informations contextuelles (nature des personnes impliquées, attitude, …) sont à qualifier en champ libre. A aborder par l’opérateur en même temps que le nombre de patients/victimes.
A31: R27 | B31: Implication de nombreuses personnes (11 et+) | C31: En vue de permettre aux forces de sécurité d’adapter leur dispositif d’intervention. Les autres informations contextuelles (nature des personnes impliquées, attitude, …) sont à qualifier en champ libre. A aborder par l’opérateur en même temps que le nombre de patients/victimes.
A32: R28 | B32: Patient/Victime incarcéré
A33: R31 | B33: Patient/Victime dans l'eau
A34: R32 | B34: Patient/Victime confiné
A35: R33 | B35: Patient/Victime violent
A36: R34 | B36: Patient/Victime vulnérable | C36: Ex : personnes mineures
A37: R35 | B37: Patient/Victime contagieux | C37: Ex : prise en charge de patients tuberculeux
A38: R37 | B38: Situation instable/indéterminée | C38: En vue d’alerter les professionnels intervenant sur place d'un possible risque de dégradation de la situation (ex: reconnaissance sur site non achevée)
A39: R60 | B39: Risque d'explosion, présence de gaz (bouteilles)
A40: R61 | B40: Présence de matière ou matériel explosif
...

Sheet Motif de recours médico-secouri
A1: Identifiant nomenclature | B1: HubSante.motif
A2: Référentiel nomenclature | B2: CISU
A3: Nom Nomenclature | B3: Code_Motif_patient-victime
A4: Nombre de niveau | B4: 3
A5: Description | B5: Décrit le motif de recours médico-secouriste.
A6: Code | B6: Libellé niveau 1 | C6: Libellé niveau 2 | D6: Libellé niveau 3 | E6: Description | F6: Commentaire
A7: M08.00.00 | B7: Personne inconsciente
A8: M08.01.00 | C8: Personne en arrêt ventilatoire
A9: M08.02.00 | C9: Personne en arrêt cardio-respiratoire
A10: M08.03.00 | C10: Personne inconsciente qui respire
A11: M09.00.00 | B11: Hémorragies / Saignements
A12: M09.01.00 | C12: Hémorragie ne pouvant être stoppée
A13: M09.01.01 | D13: Epitaxis non stoppée par compression
A14: M09.02.00 | C14: Hémorragie extériorisée
A15: M09.02.01 | D15: Hémorragie digestive (haute ou basse) extériorirée
A16: M09.02.02 | D16: Hémorragie extériorisée avec malaise
A17: M09.02.03 | D17: Crache du sang hémoptysie
A18: M09.02.04 | D18: Saignement stoppé par compression
A19: M09.02.05 | D19: Epistaxis stoppée par compression
A20: M09.03.00 | C20: Saignements bénins
A21: M09.03.01 | D21: Saignement bénin sans signe de gravité identifié
A22: M10.00.00 | B22: Problème circulatoire
A23: M10.01.00 | C23: Palpitations
A24: M10.02.00 | C24: Autres troubles circulatoires
A25: M10.02.01 | D25: Patient/victime choquée par défibrillateur implanté
A26: M10.02.02 | D26: Bradycardie < 50 ou tachycardie > 150
A27: M10.02.03 | D27: Pression Artérielle < 90 mmHg
A28: M10.02.04 | D28: Pression Artérielle > 160 mmHg
A29: M10.02.05 | D29: Autre trouble sans signe de gravité
A30: M11.00.00 | B30: Problème respiratoire
A31: M11.01.00 | C31: Détresse respiratoire
A32: M11.01.01 | D32: Détresse respiratoire avec asphyxie | E32: Moins de 4 syllabes ou mots courts, cyanose), ou obstruction complète
A33: M11.01.02 | D33: Epuisement respiratoire chez un nourrisson
A34: M11.02.00 | C34: Difficultés respiratoires
A35: M11.02.01 | D35: Respiration bruyante
A36: M11.02.02 | D36: Difficultés respiratoires avec sueurs ou altération de conscience
A37: M11.02.03 | D37: Difficultés respiratoires sans signe de gravité
A38: M11.03.00 | C38: Autres problèmes respiratoires
A39: M11.03.01 | D39: Problème isolé d'appareillage respiratoire ou canule
A40: M11.03.02 | D40: Corps étranger expulsé des poumons
...

Sheet Etats du dossier
A1: Identifiant nomenclature | B1: HubSante.etat
A2: Référentiel nomenclature | B2: ENUM
A3: Nom Nomenclature | B3: Etats_Dossier
A4: Nombre de niveau | B4: 1
A5: Description | B5: Décrit la filière compétente pour traiter le dossier.
A6: Code | B6: Libellé niveau 1 | C6: Libellé niveau 2 | D6: Description | E6: Commentaire
A7: PROGRAM | B7: Programmé | D7: L'état « Programmé » est spécifique au DRM, il correspond à une création de dossier en avance de phase. Il est en particulier utilisé pour les TIH, dossiers pour lesquels la future régulation et prise en charge est connue. Un dossier à l’état « Programmé » contient la date et l’heure à laquelle le dossier doit s’activer.
A8: ACTIF | B8: Actif | D8: L'état « Actif » est un premier stade d’un dossier dans le cycle de vie (en dehors de l’état « Programmé » qui ne fait pas partie des états par lesquels passe l’ensemble des dossiers). L’état « Actif » qualifie le début de la prise en charge du dossier (au décroché de l’appel) et la phase de régulation médicale, cet état concerne l’ensemble des dossiers en cours d’instruction.
A9: ACHEVE | B9: Achévé | D9: L’état « Achevé » qualifie la fin de la phase active du dossier. Le dossier atteint l’état « Achevé » dès lors toutes les décisions possibles ont été prises et que les actions découlant de ces décisions ont été menées à leur terme : - Les patients sont arrivés à destination, - La prise en charge des patients a été assurée et est conforme à la décision prise, - Les véhicules sont arrivés à destination et ne transportent plus aucuns patients, - Les équipes d’intervention n’ont plus de patients en charge. Les dossiers à l’état « Achevé » restent modifiables par les agents du CRRA.
A10: VALIDE | B10: Validé | D10: L’état « Validé » marque la fin de la phase de régulation médicale. Le dossier passe automatiquement à l’état « Validé » dès lors : - Qu’il est complet (il contient toutes les informations et codifications obligatoires), - Qu’il est cohérent, - Que les identités des patients ont été vérifiées (contrôle optionnel). Tout dossier à l’état « Validé » reste modifiable (les notes et observations déjà présentes sont figées mais de nouvelles notes et observations peuvent être rédigées). Par ailleurs de nouvelles décisions peuvent être prises (en fonction de l’évolution de la situation du patient) ce qui a pour effet de renvoyer le dossier au début de son cycle de vie, à savoir à l’état « Actif ».
A11: CLOTURE | B11: Cloturé | D11: Etat « Clôturé » : tout dossier à l’état « Validé » passera à l’état « Clôturé » 24 heures après son passage à l’état « Actif ». Dès lors que le dossier est à l’état « Clôturé », le dossier n’est plus modifiable, sauf autorisation spécifique sur des champs précis. Par ailleurs, contrairement à l’état « Validé », un dossier à l’état « Clôturé » n’est plus réactivable (tout nouvel appel concernant le dossier qui nécessiterait une nouvelle prise de décision conduirait à l’ouverture d’un nouveau dossier). L’état « Clôturé » incarne la phase médico-administrative du dossier permettant la bonne tenue des tâches suivantes : - tâches médicales pour certains DRM : contrôles qualité, certificats médicaux, attestations, courriers au médecin traitant… - tâches de secrétariat et actions administratives : prescriptions de transport, contrôles qualité, courriers, pré facturations, facturations, etc.
A12: CLASSE | B12: Classé | D12: Etat « Classé » : le passage à l’état « Classé » incarne la fin de la phase médico-administrative. Le dossier atteint cet état dès lors qu’il est à l’état « Clôturé ». Tout dossier à l’état « Classé » n’est plus modifiable (seules des notes peuvent être ajoutées par certains utilisateurs autorisés). Le passage à l’état « Classé » est par ailleurs automatique 3 mois après l’ouverture du dossier.
A13: ARCHIVE | B13: Archivé | D13: Etat « Archivé » : un dossier passera à l’état « Archivé » dès lors qu’il est à l’état « Classé » et qu’il respecte toutes les obligations du test d’archivage. Dès lors que le dossier est « Archivé », toute modification de champs devient impossible. Le dossier n’est par ailleurs plus disponible dans le SI-Samu (les données utiles à des fins statistiques seront anonymisées dans le respect des règles en vigueur et conservées dans les bases de données existantes). L’archivage ne pourra être réalisé qu’après un délai minimal à respecter (ex : 2 ou 5 ans)

Sheet Nombre de patients-victimes
A1: Identifiant nomenclature | B1: HubSante.nbVictimes
A2: Référentiel nomenclature | B2: ENUM
A3: Nom Nomenclature | B3: NOMBRE_Patient_Victime
A4: Nombre de niveau | B4: 1
A5: Description | B5: Décrit le nombre de patient/victimes
A6: Code | B6: Libellé niveau 1 | C6: Libellé niveau 2 | D6: Description | E6: Commentaire
A7: 0 | B7: 0
A8: 1 | B8: 1
A9: PLUSIEURS | B9: PLUSIEURS
A10: BEAUCOUP | B10: BEAUCOUP
A11: INCONNU | B11: INCONNU
A12: NON DEFINI | B12: NON DEFINI

Sheet Type du patient-victime
A1: Identifiant nomenclature | B1: HubSante.patient
A2: Référentiel nomenclature | B2: ENUM
A3: Nom Nomenclature | B3: TYPE_Patient_Victime
A4: Nombre de niveau | B4: 1
A5: Description | B5: Décrit le type de patient/victime principal
A6: Code | B6: Libellé niveau 1 | C6: Libellé niveau 2 | D6: Description | E6: Commentaire
A7: NOURRISSON | B7: NOURRISSON
A8: ENFANT | B8: ENFANT
A9: ADULTE | B9: ADULTE
A10: SENIOR | B10: SENIOR
A11: ENCEINTE | B11: ENCEINTE

Sheet Attribution du dossier
A1: Identifiant nomenclature | B1: HubSante.attribution
A2: Référentiel nomenclature | B2: SI-SAMU
A3: Nom Nomenclature | B3: DEVENIRD
A4: Nombre de niveau | B4: 3
A5: Description | B5: Décrit le type de dossier, et son attribution
A6: Code | B6: Libellé niveau 1 | C6: Libellé niveau 2 | D6: Libellé niveau 3 | E6: Description | F6: Commentaire
A7: DRM | B7: DRM | E7: Dossier de régulation médicale
A8: DRM.MRU | C8: DRM MRU | E8: Dossier de type médecine d’urgence
A9: DRM.MRU.MU | D9: Régulation MU | E9: Dossier de type médecine d’urgence régulé par un médecin urgentiste. Le dossier devient de type DRM
A10: DRM.MRU.INDISPMU | D10: Régulation ML par indisponibilité MU | E10: Dossier de type médecine d'urgence régulé par un médecin libéral du fait de l’indisponibilité des MU. Le dossier devient de type DRM
A11: DRM.MRU.SSE | D11: Régulation de crise - NOVI | E11: Dossier relevant de la gestion de crise – NOmbreuses Victimes. Le dossier devient de type DRM
A12: DRM.MRU.PLANBLAN | D12: Régulation Plan Blanc | E12: Dossier régulé dans le cadre d’ un dispositif plan blanc. Le dossier devient de type DRM
A13: DRM.MRU.PCSAMU | D13: Régulation par un PC mobile | E13: Dossier régulé depuis un poste de commandement mobile. Le dossier devient de type DRM
A14: DRM.SPE | C14: DRM SPE
A15: DRM.SPE.DENT | D15: Régulation dentaire | E15: Dossier régulé par un chirurgien dentiste au sein du CRRA. Le dossier devient de type DRM
A16: DRM.SPE.GERIA | D16: Régulation gériatrique | E16: Dossier régulé par un gériatre au sein du CRRA. Le dossier devient de type DRM
A17: DRM.SPE.PEDIA | D17: Régulation pédiatrie | E17: Dossier régulé par un pédiatre au sein du CRRA. Le dossier devient de type DRM
A18: DRM.SPE.OBST | D18: Régulation obstétrique | E18: Dossier relevant d'une coordination périnatale. Le dossier devient de type DRM
A19: DRM.SPE.PSY | D19: Régulation psychiatrie | E19: Dossier régulé par un psychiatre au sein du CRRA. Le dossier devient de type DRM
A20: DRM.SPE.TOXICOL | D20: Régulation toxicologique | E20: Dossier régulé par un toxicologue au sein du CRRA. Le dossier devient de type DRM
A21: DRM.SPE.AUTRESPE | D21: Régulation autre spécialité
A22: DRM.MRL | C22: DRM MRL | E22: Dossier de type médecine libérale
A23: DRM.MRL.MG | D23: Régulation ML | E23: Dossier de type médecine libérale régulé par un médecin libéral. Le dossier devient de type DRM
A24: DRM.MRL.INDISPMG | D24: Régulation MU par indisponibilité ML | E24: Dossier de type médecine libérale régulé par un médecin urgentiste du fait de l’indisponibilité des ML. Le dossier devient de type DRM
A25: DRM.MRL.ABSML | D25: Régulation MU par absence de régulation ML | E25: Dossier de type médecine libérale régulé par un médecin urgentiste du fait de l’absence de régulation ML. Le dossier devient de type DRM
A26: DR | B26: DR | E26: Dossier de régulation
A27: DR.DREG | C27: Dossier Régulation | E27: Dossier de régulation
A28: DR.DREG.DRARM | D28: Pas d’acte de régulation médicale - Prise en charge ARM | E28: Dossier ne relevant pas de la régulation médicale et pas dans le cadre des autre cas identifié (voir cas suivant). Le dossier est de type DR
A29: DR.DREG.DRDAC | D29: Pas d’acte de régulation médicale - Prise en charge DAC
A30: DR.DREG.DRMED | D30: Pas d’acte de régulation médicale - Transmission d'informations sur un médecin (procédure dégradée) | E30: Dossier ne relevant pas de la régulation médicale – réponse apportée à une demande de renseignements sur un médecin. Le dossier est de type DR
A31: DR.DREG.DRPHARMA | D31: Pas d’acte de régulation médicale - Transmission d'informations sur une pharmacie | E31: Dossier ne relevant pas de la régulation médicale – réponse apportée à une demande de renseignements sur une pharmacie. Le dossier est de type DR
A32: DR.DREG.DRDENT | D32: Pas d’acte de régulation médicale - Transmission d'informations sur un dentiste | E32: Dossier ne relevant pas de la régulation médicale – réponse apportée à une demande de renseignements sur un dentiste. Le dossier est de type DR
A33: DR.DREG.DRINFO | D33: Pas d’acte de régulation médicale - Information générale | E33: Dossier ne relevant pas de la régulation médicale – réponse apportée à une demande de renseignements d’ordre général. Le dossier est de type DR
A34: DR.DREG.DOS-SIS | D34: Pas d’acte de régulation médicale - Appel pour les pompiers | E34: Dossier ne rentrant pas dans le cadre des missions du Samu et confié aux pompiers. Le dossier est de type DR
A35: DR.DREG.DOS-FDO | D35: Pas d’acte de régulation médicale - Appel pour les forces de l’ordre | E35: Dossier ne rentrant pas dans le cadre des missions du Samu et confié aux forces de l'ordre. Le dossier est de type DR
A36: D | B36: D | E36: Dossier
A37: D.D-MALV | C37: Erreur / Malveillant | E37: Dossier de type erreur ou appel malveillant
A38: D.D-MALV.ERR | D38: Erreur de numéro, erreur d'acheminement | E38: Le requérant s’est trompé de numéro de téléphone ou a mal été orienté par un interlocuteur précédent. Le dossier reste de type D
A39: D.D-MALV.NRP | D39: Appel raccroché / pas de réponse | E39: L’appel est raccroché ou sans réponse de l’appelant à l’ouverture du dossier. Le dossier reste de type D
A40: D.D-MALV.MALV | D40: Appel malveillant, canular | E40: Appel malveillant : insultes, canular, fausses informations. Il ne s’agit pas d’une erreur de numéro. Le dossier reste de type D
...

Sheet Priorité de régulation médicale
A1: Identifiant nomenclature | B1: HubSante.priorite
A2: Référentiel nomenclature | B2: SI-SAMU
A3: Nom Nomenclature | B3: PRIORITE
A4: Nombre de niveau | B4: 1
A5: Description | B5: Décrit la priorité de régulation médicale.
A6: Code | B6: Libellé niveau 1 | C6: Libellé niveau 2 | D6: Libellé niveau 3 | E6: Description | F6: Commentaire
A7: P0 | B7: Urgence vitale | E7: Régulation médicale pour une urgence vitale
A8: P1 | B8: Prioritaire | E8: Régulation médicale urgente et prioritaire
A9: P2 | B9: Non Urgent | E9: Régulation médicale non urgente (valeur attribuée par défaut)
A10: P3 | B10: Différé | E10: Régulation médicale différée
A11: NR | B11: Non régulé | E11: Pas d’acte de régulation médicale

Sheet Lieu - Source ou type d'id
A1: Identifiant nomenclature | B1: HubSante.idLieu
A2: Référentiel nomenclature | B2: ENUM
A3: Nom Nomenclature | B3: SOURCE_Id_Lieu
A4: Nombre de niveau | B4: 1
A5: Description | B5: Décrit le type d'idenfiant possible pour un lieu (société / établissement)
A6: Code | B6: Libellé niveau 1 | C6: Libellé niveau 2 | D6: Description | E6: Commentaire
A7: FINESS_ADMINISTRATIF | B7: FINESS_ADMINISTRATIF
A8: FINESS_GEOGRAPHIQUE | B8: FINESS_GEOGRAPHIQUE
A9: SIREN | B9: SIREN
A10: SIRET | B10: SIRET
A11: APE_NAF | B11: APE_NAF

Sheet Precision
A1: Identifiant nomenclature | B1: HubSante.precision
A2: Référentiel nomenclature | B2: ENUM
A3: Nom Nomenclature | B3: PRECISION
A4: Nombre de niveau | B4: 1
A5: Description | B5: Décrit le niveau de précision des coordonnées GPS envoyées
A6: Code | B6: Libellé niveau 1 | C6: Libellé niveau 2 | D6: Description | E6: Commentaire
A7: VILLE | B7: VILLE | D7: Précision à l'échelle de la ville
A8: RUE | B8: RUE | D8: Précision à l'échelle de la rue
A9: ADRESSE | B9: ADRESSE | D9: Adresse précise
A10: EXACTE | B10: EXACTE | D10: Point coordonnée GPS exact
A11: INCONNUE | B11: INCONNUE | D11: Précision de la localisation non évaluable par l'émetteur

Sheet Nom de la source
A1: Identifiant nomenclature | B1: HubSante.systeme
A2: Référentiel nomenclature | B2: ENUM
A3: Nom Nomenclature | B3: SOURCE_Loc
A4: Nombre de niveau | B4: 1
A5: Description | B5: Décrit le système fournissant le localisant
A6: Code | B6: Libellé niveau 1 | C6: Libellé niveau 2 | D6: Description | E6: Commentaire
A7: BAN | B7: BAN
A8: IGN | B8: IGN
A9: NEXSIS | B9: NEXSIS

Sheet Type d'objet
A1: Identifiant nomenclature | B1: HubSante.objetSource
A2: Référentiel nomenclature | B2: ENUM
A3: Nom Nomenclature | B3: TYPE_Objet_Sys
A4: Nombre de niveau | B4: 1
A5: Description | B5: Décrit le type d'objet dans le système
A6: Code | B6: Libellé niveau 1 | C6: Libellé niveau 2 | D6: Description | E6: Commentaire
A7: MANUEL | B7: MANUEL
A8: CARTE | B8: CARTE
A9: AUTRE | B9: AUTRE
A10: PHOTO | B10: PHOTO
A11: SITE_INTERNET | B11: SITE_INTERNET

Sheet Signalement
A1: Identifiant nomenclature | B1: HubSante.signalement
A2: Référentiel nomenclature | B2: ENUM
A3: Nom Nomenclature | B3: SIGNALEMENT
A4: Nombre de niveau | B4: 1
A5: Description | B5: Décrit le niveau de signalement de l'alerte
A6: Code | B6: Libellé niveau 1 | C6: Libellé niveau 2 | D6: Description | E6: Commentaire
A7: STANDARD | B7: STANDARD
A8: ATTENTION | B8: ATTENTION

Sheet Canal
A1: Identifiant nomenclature | B1: HubSante.canal
A2: Référentiel nomenclature | B2: ENUM
A3: Nom Nomenclature | B3: CONTACT_Canal
A4: Nombre de niveau | B4: 1
A5: Description | B5: Décrit le type de canal utilisé pour le contact
A6: Code | B6: Libellé niveau 1 | C6: Libellé niveau 2 | D6: Description | E6: Commentaire
A7: APPLICATION | B7: APPLICATION
A8: BAU | B8: BAU
A9: DAU | B9: DAU
A10: DEFIBRILLATEUR | B10: DEFIBRILLATEUR
A11: ECALL | B11: ECALL
A12: PERSONNE | B12: PERSONNE

Sheet Type de contact
A1: Identifiant nomenclature | B1: HubSante.typeCom
A2: Référentiel nomenclature | B2: ENUM
A3: Nom Nomenclature | B3: CONTACT_Type
A4: Nombre de niveau | B4: 1
A5: Description | B5: Décrit le type de contact
A6: Code | B6: Libellé niveau 1 | C6: Libellé niveau 2 | D6: Description | E6: Commentaire
A7: EMAIL | B7: EMAIL
A8: FAX | B8: FAX
A9: MSS | B9: MSS
A10: POSTAL | B10: POSTAL
A11: RADIO | B11: RADIO
A12: TEL | B12: TEL
A13: WEB | B13: WEB

Sheet Langue
A1: Identifiant nomenclature | B1: HubSante.langue
A2: Référentiel nomenclature | B2: ISO-639.1
A3: Nom Nomenclature | B3: LANGUE
A4: Nombre de niveau | B4: 1
A5: Description | B5: Décrit la langue parlée par l'appelant / le requérant. Source : https://www.loc.gov/standards/iso639-2/php/code_list.php
A6: Code | B6: Libellé niveau 1 | C6: Libellé niveau 2 | D6: Libellé niveau 3 | E6: Description | F6: Commentaire
A7: aa | B7: Afar | C7: afar
A8: ab | B8: Abkhazian | C8: abkhaze
A9: ae | B9: Avestan | C9: avestique
A10: af | B10: Afrikaans | C10: afrikaans
A11: ak | B11: Akan | C11: akan
A12: am | B12: Amharic | C12: amharique
A13: an | B13: Aragonese | C13: aragonais
A14: ar | B14: Arabic | C14: arabe
A15: as | B15: Assamese | C15: assamais
A16: av | B16: Avaric | C16: avar
A17: ay | B17: Aymara | C17: aymara
A18: az | B18: Azerbaijani | C18: azéri
... A189: zu | B189: Zulu | C189: zoulou

Sheet Type de requérant
A1: Identifiant nomenclature | B1: HubSante.typeAppelant
A2: Référentiel nomenclature | B2: SI-SAMU
A3: Nom Nomenclature | B3: TYPAPPLT
A4: Nombre de niveau | B4: 2
A5: Description | B5: Décrit le type de requérant/appelant
A6: Code | B6: Libellé niveau 1 | C6: Libellé niveau 2 | D6: Description | E6: Commentaire
A7: SUJET | B7: Le patient lui-même | D7: Le patient lui-même, victime de l’événement signalé et bénéficiaire des moyens qui pourraient être décidés même s’il a une des fonctions ou titres ci-dessous.
A8: FAMILLE | B8: Famille ou proche du patient | D8: Requérant qui se présente comme membre de la famille ou proche (concubin, compagnon, colocataire, ...) de la victime de l’événement signalé même s’il a un des titres ou une des fonctions ci-dessous.
A9: TIERS | B9: Autre particulier ou passant | D9: Particulier qui n’a pas une des fonctions ou titres ci-dessous et qui ne fait pas partie de la famille de la victime.
A10: POMPIER | B10: Pompier | D10: Le requérant est un pompier professionnel ou volontaire en activité et agissant dans le cadre de sa profession au moment de l’appel.
A11: AMBULANC | B11: Ambulancier | D11: Le requérant est un ambulancier agissant dans le cadre de sa profession au moment de l’appel.
A12: AMBULANC.AASC | C12: Secouriste aasc | D12: Pour tout secouriste actif d'une association aggrée de sécurité civile et n’est pas un professionnel de santé.
A13: AMBULANC.AUTRESEC | C13: Autre secouriste | D13: Secouriste du travail ou requerant qui se revendique secouriste
A14: SECOUR | B14: Secouriste actif | D14: Pour tout secouriste actif ( secouriste du travail ou agissant pour une association de secourisme) mais uniquement s’il est en activité et n’est pas un professionnel de santé.
A15: MED | B15: Médecin | D15: Regroupe les médecins de toute spécialité, de tout statut mais uniquement s’ils sont en activité et agissent dans le cadre de leur profession au moment de l’appel.
A16: MED.MEDSOS | C16: Médecin SOS ou association PDS | D16: Déclinaison du type Médecin : Regroupe les médecins SOS, uniquement s’ils sont en activité et agissent dans le cadre de leur profession au moment de l’appel.
A17: MED.MRL | C17: Médecin régulateur libéral | D17: Déclinaison du type Médecin : Regroupe les demandes issues des médecins régulateurs généralistes lorsque le DRM n’est pas encore créé dans le SI-Samu (par exemple quand il a été jusque-là uniquement renseigné dans un SI-PDSA).
A18: MED.EFFML | C18: Effecteur de médecine libérale | D18: Déclinaison du type Médecin : Regroupe les demandes issues des médecins effecteurs de médecine générale (hors médecins de SOS ou association de PDSA) lorsque le DRM n’est pas encore créé dans le SI-Samu (par exemple quand il a été jusque-là uniquement renseigné dans un SI-PDSA).
A19: SANTE | B19: Autre acteur de santé | D19: Regroupe tous les autres professionnels de santé, de toute spécialité, de tout statut mais uniquement s’ils sont en activité et agissent dans le cadre de leur profession au moment de l’appel.
A20: SANTE.INF | C20: Infirmier | D20: Regroupe les infirmiers de toute spécialité, de tout statut mais uniquement s’ils sont en activité et agissent dans le cadre de leur profession au moment de l’appel.
A21: SANTE.AIDESOIN | C21: Aide-soignant | D21: Regroupe les aides-soignants, de tout statut mais uniquement s’ils sont en activité et agissent dans le cadre de leur profession au moment de l’appel.
A22: SANTE.SF | C22: Sage-femme | D22: Regroupe les sage-femmes, de tout statut mais uniquement s’ils sont en activité et agissent dans le cadre de leur profession au moment de l’appel.
A23: SANTE.AIDEDOM | C23: Aide à domicile | D23: Regroupe les aides à domicile, de tout statut mais uniquement s’ils sont en activité et agissent dans le cadre de leur profession au moment de l’appel.
A24: SANTE.PHARMA | C24: Pharmacien | D24: Regroupe les pharmaciens, de tout statut mais uniquement s’ils sont en activité et agissent dans le cadre de leur profession au moment de l’appel.
A25: SANTE.DENTISTE | C25: Dentiste | D25: Regroupe les dentistes, de tout statut mais uniquement s’ils sont en activité et agissent dans le cadre de leur profession au moment de l’appel.
A26: SANTE.LABO | C26: Personnel de laboratoire | D26: Regroupe lespersonnels de laboratoires, de tout statut mais uniquement s’ils sont en activité et agissent dans le cadre de leur profession au moment de l’appel.
A27: FDO-MILI | B27: Policier Gendarme Militaire | D27: Regroupe tout policier, gendarme, militaire de tout statut et de tout grade mais uniquement s’il est en activité et n’est pas un professionnel de santé ou un secouriste actif.
A28: FDO-MILI.POL | C28: Policier
A29: FDO-MILI.GENDARM | C29: Gendarme
A30: FDO-MILI.MILI | C30: Militaire
A31: ADM-TUTL | B31: Membre d'une autorité administrative | D31: L’appelant est issu d’une autorité administrative (de tutelle) et appelle les services d’urgence dans le cadre de ses fonctions (ex : ARS, Ministère de la santé, HAS…)
A32: VIP | B32: VIP | D32: Personne publique, de notoriété ou élus Mais qui n'est pas une autorité administrative
A33: OBJCONNC | B33: Objets connectés | D33: L’appelant initial n’est pas une personne physique mais un objet connecté en mesure de passer des appels d’urgences (ex : automobile dans le cadre des appels e-call)
A34: AUTRE | B34: Autre type d’appelant | D34: Pour toutes les fonctions non prévues ci-dessus.
A35: INCONNU | B35: Type d'appelant indéterminé | D35: Si la fonction ou le titre de l'appelant est inconnu.

Sheet Difficultés de communication
A1: Identifiant nomenclature | B1: HubSante.communication
A2: Référentiel nomenclature | B2: SI-SAMU
A3: Nom Nomenclature | B3: PBAPL
A4: Nombre de niveau | B4: 1
A5: Description | B5: Décrit les difficultés de communication potentielles du requérant/appelant
A6: Code | B6: Libellé niveau 1 | C6: Libellé niveau 2 | D6: Libellé niveau 3 | E6: Description | F6: Commentaire
A7: AUCUNE | B7: Aucune difficulté de communication | E7: Aucune difficulté de communication rencontrée entre l’appelant et la personne qualifiant ou régulant le dossier.
A8: MUET | B8: Muet ou malentendant (troubles de la parole ou de l'audition) | E8: Difficultés de communication liées aux caractéristiques de l’appelant, muet ou ayant des troubles prononcés de l’élocution, malentendant ou ayant des troubles prononcés de l’audition ne lui permettant pas d’interagir dans de bonnes conditions avec son interlocuteur du CRRA
A9: VISION | B9: Malvoyant, troubles de la vision | E9: Difficultés de communication liées aux caractéristiques de l’appelant, malvoyant ou ayant des troubles prononcés de la vue ne lui permettant pas de décrire correctement la situation pour laquelle il appelle
A10: LANGUE | B10: Barrière de la langue (langue étrangère) | E10: Difficultés de communication avec l’appelant liées au fait que l’appelant ne comprend pas ou mal le français ou ne le parle pas ou mal
A11: PANIQUE | B11: Panique de l’appelant | E11: Difficultés de communication avec l’appelant liées à une situation de stress extrême ou de panique de l’appelant, du patient ou de l’entourage ne lui permettant pas de décrire correctement la situation pour laquelle il appelle
A12: HOSTILE | B12: Appelant hostile, agressif | E12: Difficultés de communication avec l’appelant liées à une situation d’hostilité ou d’agressivité de l’appelant ne permettant pas une bonne compréhension du problème pour lequel il appelle
A13: AGITE | B13: Incohérence, agitation, intoxication | E13: Patient psychiatrique ayant des difficultés pour exprimer sa plainte ou patient alcoolisé, agité et incohérent dans l’incapacité de formuler les raisons de son appel
A14: AUTRE | B14: Autres difficultés de communication | E14: Autres troubles humains ou techniques, de l’appelant ou de l’entourage, empêchant la bonne interaction entre l’appelant et la personne qualifiant ou régulant le dossier et la bonne compréhension de la situation pour laquelle il appelle
A15: IMPOSS | B15: Absence de communication | E15: Pas de communication possible avec l’appelant (ex : pas d'echange vocal, appel raccroché prématurement sans contre appel possible, ...)

Sheet Patient - type d'Id
A1: Identifiant nomenclature | B1: HubSante.typeIdPatient
A2: Référentiel nomenclature | B2: ENUM
A3: Nom Nomenclature | B3: TYPE_Id_Patient
A4: Nombre de niveau | B4: 1
A5: Description | B5: Décrit le type d'identifiant fourni
A6: Code | B6: Libellé niveau 1 | C6: Libellé niveau 2 | D6: Description | E6: Commentaire
A7: NIR | B7: NIR | D7: Numéro d'identification NIR ou NIA
A8: SINUS | B8: SINUS | D8: Numéro d'identification SINUS
A9: DOSSARD | B9: DOSSARD | D9: Numéro de dossard
A10: PLACE | B10: PLACE | D10: Numéro de place
A11: AUTRE | B11: AUTRE | D11: Autre identifiant

Sheet Sexe
A1: Identifiant nomenclature | B1: HubSante.sexe
A2: Référentiel nomenclature | B2: NOS
A3: Nom Nomenclature | B3: NOMENC_SEXE
A4: Nombre de niveau | B4: 1
A5: Description | B5: Décrit le sexe du patient
A6: Code | B6: Libellé niveau 1 | C6: Libellé niveau 2 | D6: Libellé niveau 3 | E6: Description | F6: Commentaire
A7: M | B7: Masculin | E7: Qualifie les individus de sexe masculin
A8: F | B8: Féminin | E8: Qualifie les individus de sexe féminin
A9: O | B9: Autre sexe (ni masculin, ni féminin) | E9: Qualifie les individus de troisième genre (individu considéré comme n ’étant ni homme ni femme, à la fois homme et femme, ou neutre)
A10: UN | B10: Inconnu | E10: Le sexe de la personne n'est pas connu

Sheet Niveau de soin
A1: Identifiant nomenclature | B1: HubSante.niveauSoin
A2: Référentiel nomenclature | B2: SI-SAMU
A3: Nom Nomenclature | B3: GRAVITE
A4: Nombre de niveau | B4: 1
A5: Description | B5: Décrit le niveau de soins : le plus grave est retenu pour qualifier le dossier/affaire. Pour chaque patient/victime, le motif spécifique est indiqué.
A6: Code | B6: Libellé niveau 1 | C6: Libellé niveau 2 | D6: Libellé niveau 3 | E6: Description | F6: Commentaire
A7: R1 | B7: Urgence Vitale | E7: Urgence vitale patente ou latente imposant l’envoi du Smur
A8: R2 | B8: Urgence vraie | E8: Urgence vraie sans détresse vitale nécessitant l’envoi d’un médecin, d’une ambulance ou d’un VSAV. Le délai d’intervention est immédiat par défaut ou contractualisé entre le médecin régulateur et le requérant
A9: R3 | B9: Continuité de soins | E9: Situation relevant de la continuité de soins. Le délai ne constituant pas un facteur de risque
A10: R4 | B10: Conseil ou PMT | E10: Situation pouvant être traitée par un conseil médical ou prescription médicamenteuse par téléphone

Sheet Role
A1: Identifiant nomenclature | B1: HubSante.role
A2: Référentiel nomenclature | B2: ENUM
A3: Nom Nomenclature | B3: ROLE
A4: Nombre de niveau | B4: 1
A5: Description | B5: Décrit le rôle de l'opérateur dans l'organisation à laquelle il appartient
A6: Code | B6: Libellé niveau 1 | C6: Libellé niveau 2 | D6: Description | E6: Commentaire
A7: AMBULANCIER | B7: Ambulancier | D7: L'opérateur est un ambulancier
A8: ARM | B8: ARM | D8: L'opérateur est un ARM
A9: INFIRMIER | B9: Infirmier | D9: L'opérateur est un infirmier
A10: MEDECIN | B10: Médecin | D10: L'opérateur est un médecin
A11: PILOTE | B11: Pilote | D11: L'opérateur est un pilote d'aéronef
A12: TCM | B12: Technicien de bord | D12: Assistant du pilote
A13: AUTRE | B13: Autre | D13: Le rôle de l'opérateur est connu, mais n'est pas détaillé dans la liste des valeurs fournie
A14: INCONNU | B14: Inconnu | D14: Le rôle de l'opérateur est inconnu

Sheet Type de decision
A1: Identifiant nomenclature | B1: HubSante.typeDecision
A2: Référentiel nomenclature | B2: SI-SAMU
A3: Nom Nomenclature | B3: TYPEDEC
A4: Nombre de niveau | B4: 2
A5: Description | B5: Décrit le type de décision prise
A6: Code | B6: Libellé niveau 1 | C6: Libellé niveau 2 | D6: Libellé niveau 3 | E6: Description | F6: Commentaire
A7: CONSEIL | B7: Conseil Médical | C7: #Conseil Médical | E7: Conduite à tenir donnée à distance par le médecin régulateur sans intervention d’un tiers. Le conseil médical peut être donné à la demande du patient ou à chaque fois que le médecin régulateur juge que l’appel ne nécessite pas un examen médical. Cette décision peut être accompagnée ou non d’une prescription médicamenteuse téléphonique.
A8: PMT | B8: Prescription médicamenteuse téléphonique | C8: #PMT | E8: Réalisation d'une prescription médicamenteuse téléphonique
A9: INTER | B9: Décision d’intervention | C9: #Intervention | E9: Décision qui implique l’envoi d’un moyen d’intervention (ressource mobile) : Smur, médical, paramédical, pompier ous transporteur sanitaire.
